<!DOCTYPE HTML PUBLIC "-//W3C//DTD HTML 4.01//EN"
    "http://www.w3.org/TR/html4/strict.dtd">
<html>
<head>
<meta charset="utf-8">
<title>Issue 1106: Multiple exceptions from connected shared_future::get()?</title>
<style type="text/css">
  p {text-align:justify}
  li {text-align:justify}
  blockquote.note
  {
    background-color:#E0E0E0;
    padding-left: 15px;
    padding-right: 15px;
    padding-top: 1px;
    padding-bottom: 1px;
  }
  ins {background-color:#A0FFA0}
  del {background-color:#FFA0A0}
  table {border-collapse: collapse;}
</style>
</head>
<body>
<p>Revised 2016-11-28 at 17:11:16 UTC</p>
<hr>
<h3><a name="1106" href="1106">1106.</a> Multiple exceptions from connected <tt>shared_future::get()</tt>?</h3>
<p><b>Section:</b> 30.6.7 [futures.shared_future] <b>Status:</b> <a href="lwg-active.html#Resolved">Resolved</a>
 <b>Submitter:</b> Thomas J. Gritzan <b>Opened:</b> 2009-04-03 <b>Last modified:</b> 2016-01-28</p>
<p><b>Priority: </b>Not Prioritized
</p>
<p><b>View all other</b> <a href="lwg-index.html#futures.shared_future">issues</a> in [futures.shared_future].</p>
<p><b>View all issues with</b> <a href="lwg-status.html#Resolved">Resolved</a> status.</p>
<p><b>Discussion:</b></p>
<p>
It is not clear, if multiple threads are waiting in a 
<tt>shared_future::get()</tt> call, if each will rethrow the stored exception.
</p>
<p>
Paragraph 9 reads: 
</p>
<blockquote><p>
<i>Throws:</i> the stored exception, if an exception was stored and not 
retrieved before.
</p></blockquote>
<p>
The "not retrieved before" suggests that only one exception is thrown, 
but one exception for each call to <tt>get()</tt> is needed, and multiple calls 
to <tt>get()</tt> even on the same <tt>shared_future</tt> object seem to be allowed. 
</p>
<p>
I suggest removing "and not retrieved before" from the Throws paragraph. 
I recommend adding a note that explains that multiple calls on <tt>get()</tt> are 
allowed, and each call would result in an exception if an exception was 
stored. 
</p>

<p><i>[
Batavia (2009-05):
]</i></p>

<blockquote>
<p>
We note there is a pending paper by Detlef
on such <tt>future</tt>-related issues;
we would like to wait for his paper before proceeding.
</p>
<p>
Alisdair suggests we may want language to clarify that this
<tt>get()</tt> function can be called from several threads
with no need for explicit locking.
</p>
<p>
Move to Open.
</p>
</blockquote>

<p><i>[
2010-01-23 Moved to Tentatively NAD Editorial after 5 positive votes on c++std-lib.
]</i></p>




<p><b>Rationale:</b></p>
<p>
Resolved by paper
<a href="http://www.open-std.org/jtc1/sc22/wg21/docs/papers/2009/n2997.htm">N2997</a>.
</p>


<p><b>Proposed resolution:</b></p>
<p>
Change 30.6.7 [futures.shared_future]:
</p>

<blockquote><pre>
const R&amp; shared_future::get() const; 
R&amp; shared_future&lt;R&amp;&gt;::get() const; 
void shared_future&lt;void&gt;::get() const;
</pre>
<blockquote>
<p>...</p>
<p>
-9- <i>Throws:</i> the stored exception, if an exception was stored<del> and not retrieved before</del>.
<ins>
[<i>Note:</i> Multiple calls on <tt>get()</tt> are allowed, and each call would result in an exception 
if an exception was stored. &mdash; <i>end note</i>]
</ins>
</p>
</blockquote>
</blockquote>






</body>
</html>
