<!DOCTYPE HTML PUBLIC "-//W3C//DTD HTML 4.01//EN"
    "http://www.w3.org/TR/html4/strict.dtd">
<html>
<head>
<meta charset="utf-8">
<title>Issue 1136: Incomplete specification of nested_exception::rethrow_nested()</title>
<style type="text/css">
  p {text-align:justify}
  li {text-align:justify}
  blockquote.note
  {
    background-color:#E0E0E0;
    padding-left: 15px;
    padding-right: 15px;
    padding-top: 1px;
    padding-bottom: 1px;
  }
  ins {background-color:#A0FFA0}
  del {background-color:#FFA0A0}
  table {border-collapse: collapse;}
</style>
</head>
<body>
<p>Revised 2016-11-30 at 07:11:35 UTC</p>
<hr>
<h3><a name="1136" href="1136">1136.</a> Incomplete specification of <tt>nested_exception::rethrow_nested()</tt></h3>
<p><b>Section:</b> 18.8.7 [except.nested] <b>Status:</b> <a href="lwg-active.html#C++11">C++11</a>
 <b>Submitter:</b> Daniel Kr&uuml;gler <b>Opened:</b> 2007-06-06 <b>Last modified:</b> 2016-01-28</p>
<p><b>Priority: </b>Not Prioritized
</p>
<p><b>View all other</b> <a href="lwg-index.html#except.nested">issues</a> in [except.nested].</p>
<p><b>View all issues with</b> <a href="lwg-status.html#C++11">C++11</a> status.</p>
<p><b>Discussion:</b></p>
<p>
It was recently mentioned in a newsgroup article
<a href="http://groups.google.de/group/comp.std.c++/msg/f82022aff68edf3d">http://groups.google.de/group/comp.std.c++/msg/f82022aff68edf3d</a>
that the specification of the member function <tt>rethrow_nested()</tt> of the
class <tt>nested_exception</tt> is incomplete, specifically it remains unclear
what happens, if member <tt>nested_ptr()</tt> returns a null value. In
18.8.7 [except.nested] we find only the following paragraph related to that:
</p>
<blockquote><pre>
void rethrow_nested() const; // [[noreturn]]
</pre>
<blockquote><p>
-4- <i>Throws:</i> the stored exception captured by this <tt>nested_exception</tt> object.
</p></blockquote>
</blockquote>
<p>
This is a problem, because it is possible to create an object of
<tt>nested_exception</tt> with exactly such a state, e.g.
</p>
<blockquote><pre>
#include &lt;exception&gt;
#include &lt;iostream&gt;

int main() try {
  std::nested_exception e; // OK, calls current_exception() and stores it's null value
  e.rethrow_nested(); // ?
  std::cout &lt;&lt; "A" &lt;&lt; std::endl;
}
catch(...) {
  std::cout &lt;&lt; "B" &lt;&lt; std::endl;
}
</pre></blockquote>
<p>
I suggest to follow the proposal of the reporter, namely to invoke
<tt>terminate()</tt> if <tt>nested_ptr()</tt> return a null value of <tt>exception_ptr</tt> instead
of relying on the fallback position of undefined behavior. This would
be consistent to the behavior of a <tt>throw;</tt> statement when no
exception is being handled.
</p>

<p><i>[
2009 Santa Cruz:
]</i></p>


<blockquote><p>
Move to Ready.
</p></blockquote>



<p><b>Proposed resolution:</b></p>
<p>
Change around 18.8.7 [except.nested] p.4 as indicated:
</p>
<blockquote>
<p>
-4- <i>Throws:</i> the stored exception captured by this <tt>nested_exception</tt>
object<ins>, if <tt>nested_ptr() != nullptr</tt></ins>
</p>
<p>
<ins>- <i>Remarks:</i> If <tt>nested_ptr() == nullptr</tt>, <tt>terminate()</tt>
shall be called.</ins>
</p>
</blockquote>





</body>
</html>
