<!DOCTYPE HTML PUBLIC "-//W3C//DTD HTML 4.01//EN"
    "http://www.w3.org/TR/html4/strict.dtd">
<html>
<head>
<meta charset="utf-8">
<title>Issue 1291: Exceptions thrown during promise::set_value</title>
<style type="text/css">
  p {text-align:justify}
  li {text-align:justify}
  blockquote.note
  {
    background-color:#E0E0E0;
    padding-left: 15px;
    padding-right: 15px;
    padding-top: 1px;
    padding-bottom: 1px;
  }
  ins {background-color:#A0FFA0}
  del {background-color:#FFA0A0}
  table {border-collapse: collapse;}
</style>
</head>
<body>
<hr>
<h3><a name="1291" href="lwg-defects.html#1291">1291.</a> Exceptions thrown during <tt>promise::set_value</tt></h3>
<p><b>Section:</b> 32.6.6 <a href="https://timsong-cpp.github.io/cppwp/futures.promise">[futures.promise]</a> <b>Status:</b> <a href="lwg-active.html#Resolved">Resolved</a>
 <b>Submitter:</b> Jonathan Wakely <b>Opened:</b> 2009-12-18 <b>Last modified:</b> 2016-01-28 10:19:27 UTC</p>
<p><b>Priority: </b>Not Prioritized
</p>
<p><b>View other</b> <a href="lwg-index-open.html#futures.promise">active issues</a> in [futures.promise].</p>
<p><b>View all other</b> <a href="lwg-index.html#futures.promise">issues</a> in [futures.promise].</p>
<p><b>View all issues with</b> <a href="lwg-status.html#Resolved">Resolved</a> status.</p>
<p><b>Discussion:</b></p>
<p>
In 32.6.6 <a href="https://timsong-cpp.github.io/cppwp/futures.promise">[futures.promise]</a>
</p>

<p>
Does <tt>promise&lt;R&gt;::set_value</tt> return normally if the copy&#47;move
constructor of <tt>R</tt> throws?
</p>

<p>
The exception could be caught and set using
<tt>promise&lt;R&gt;::set_exception</tt>, or it could be allowed to leave the
<tt>set_value</tt> call, but it's not clear which is intended. I suggest the
exception should not be caught.
</p>

<p>
N.B. This doesn't apply to <tt>promise&lt;R&amp;&gt;::set_value</tt> or
<tt>promise&lt;void&gt;::set_value</tt> because they don't construct a new
object.
</p>

<p><i>[
2010 Pittsburgh:  Moved to <del>NAD Editorial</del><ins>Resolved</ins>.  Rationale added below.
]</i></p>




<p><b>Rationale:</b></p>
<p>
Solved by
<a href="http://www.open-std.org/jtc1/sc22/wg21/docs/papers/2010/n3058.html">N3058</a>.
</p>


<p><b>Proposed resolution:</b></p>
<p>
Change 32.6.6 <a href="https://timsong-cpp.github.io/cppwp/futures.promise">[futures.promise]</a>/18:
</p>

<blockquote><p>
18 <i>Throws:</i> <tt>future_error</tt> if its associated state is already
ready<ins> or, for the first version an exception thrown by the copy constructor
of <tt>R</tt>, or for the second version an exception thrown by the move
constructor of <tt>R</tt></ins>.
</p></blockquote>





</body>
</html>
