<!DOCTYPE HTML PUBLIC "-//W3C//DTD HTML 4.01//EN"
    "http://www.w3.org/TR/html4/strict.dtd">
<html>
<head>
<meta charset="utf-8">
<title>Issue 2135: Unclear requirement for exceptions thrown in condition_variable::wait()</title>
<style type="text/css">
  p {text-align:justify}
  li {text-align:justify}
  blockquote.note
  {
    background-color:#E0E0E0;
    padding-left: 15px;
    padding-right: 15px;
    padding-top: 1px;
    padding-bottom: 1px;
  }
  ins {background-color:#A0FFA0}
  del {background-color:#FFA0A0}
  table {border-collapse: collapse;}
</style>
</head>
<body>
<hr>
<h3><a name="2135" href="lwg-defects.html#2135">2135.</a> Unclear requirement for exceptions thrown in <tt>condition_variable::wait()</tt></h3>
<p><b>Section:</b> 32.5.3 <a href="https://timsong-cpp.github.io/cppwp/thread.condition.condvar">[thread.condition.condvar]</a>, 32.5.4 <a href="https://timsong-cpp.github.io/cppwp/thread.condition.condvarany">[thread.condition.condvarany]</a> <b>Status:</b> <a href="lwg-active.html#C++14">C++14</a>
 <b>Submitter:</b> Pete Becker <b>Opened:</b> 2012-03-06 <b>Last modified:</b> 2015-10-03 16:38:46 UTC</p>
<p><b>Priority: </b>Not Prioritized
</p>
<p><b>View all other</b> <a href="lwg-index.html#thread.condition.condvar">issues</a> in [thread.condition.condvar].</p>
<p><b>View all issues with</b> <a href="lwg-status.html#C++14">C++14</a> status.</p>
<p><b>Discussion:</b></p>

<p>
<tt>condition_varible::wait()</tt> (and, presumably, <tt>condition_variable_any::wait()</tt>, although 
I haven't looked at it) says that it calls <tt>lock.unlock()</tt>, and if <tt>condition_variable::wait()</tt> 
exits by an exception it calls <tt>lock.lock()</tt> on the way out. But if the initial call to 
<tt>lock.unlock()</tt> threw an exception, does it make sense to call <tt>lock.lock()</tt>? We simply 
don't know the state of that lock object, and it's probably better not to touch it.
<p/>
That aside, once the <tt>wait()</tt> call has been unblocked, it calls <tt>lock.lock()</tt>. If <tt>lock.lock()</tt> 
throws an exception, what happens? The requirement is:
</p>
<blockquote><p>
If the function exits via an exception, <tt>lock.lock()</tt> shall be called prior to exiting the function scope.
</p></blockquote>
<p>
That can be read in two different ways. One way is as if it said "<tt>lock.lock()</tt> shall have been called &hellip;", 
i.e. the original, failed, call to <tt>lock.lock()</tt> is all that's required. But a more natural reading is 
that wait has to call <tt>lock.lock()</tt> again, even though it already failed.
<p/>
I think this wording suffers from being too general. There are two possible exception sources: the initial call 
to <tt>lock.unlock()</tt> and the final call to <tt>lock.lock()</tt>. Each one should have its own requirement. 
Lumping them together muddles things.
</p>

<p><i>[2012, Portland: move to Open]</i></p>

<p>
Pablo: <tt>unlock</tt> failing is easy -- the call leaves it locked.
       The second case, trying to <tt>lock</tt> fails -- what can you do?
       This is an odd state as we <em>had</em> it locked before was called wait.
       Maybe we should call <tt>terminate</tt> as we cannot meet the post-conditions.
       We could throw a different exception.
</p>
<p>
Hans: calling <tt>terminate</tt> makes sense as we're likely to call it soon anyway
      and at least we have some context.
</p>
<p>
Detlef: what kind of locks might be being used?
</p>
<p>
Pablo: condition variables are 'our' locks so this is less of a problem.
       <tt>condition_variable_any</tt> might be more problematic.
</p>
<p>
The general direction is to call <tt>terminate</tt> if the lock cannot be reacquired.
</p>
<p>
Pablo: Can we change the wording to 'leaves the mutex locked' ?
</p>
<p>
Hans: so if the <tt>unlock</tt> throws we simply propagate the exception.
</p>
<p>
Move the issue to open and add some formal wording at a later time.
</p>

<p><i>[2013-09 Chicago: Resolved]</i></p>


<p>
Detlef improves wording. Daniel suggests to introduce a <i>Remarks</i> element for the special
"If the function fails to meet the postcondition..." wording and applies this to the proposed
wording.
</p>



<p><b>Proposed resolution:</b></p>
<p>This wording is relative to N3691.</p>

<ol>
<li><p>Edit 32.5.3 <a href="https://timsong-cpp.github.io/cppwp/thread.condition.condvar">[thread.condition.condvar]</a> as indicated:</p>

<blockquote><pre>
void wait(unique_lock&lt;mutex&gt;&amp; lock);
</pre><blockquote>
<p>
[&hellip;]
<p/>
-10- <i>Effects:</i>
</p>
<ul>
<li><p>Atomically calls <tt>lock.unlock()</tt> and blocks on <tt>*this</tt>.</p></li>
<li><p>When unblocked, calls <tt>lock.lock()</tt> (possibly blocking on the lock), then returns.</p></li>
<li><p>The function will unblock when signaled by a call to <tt>notify_one()</tt> or a call to <tt>notify_all()</tt>,
or spuriously.</p></li>
<li><p><del>If the function exits via an exception, <tt>lock.lock()</tt> shall be called prior to exiting the function
scope.</del></p></li>
</ul>
<p>
<ins>-?- <i>Remarks:</i> If the function fails to meet the postcondition, <tt>std::terminate()</tt> shall be called 
(14.5.1 <a href="https://timsong-cpp.github.io/cppwp/except.terminate">[except.terminate]</a>). [<i>Note:</i> This can happen if the re-locking of the mutex throws an 
exception. &mdash; <i>end note</i>]</ins>
<p/>
-11- <i>Postcondition:</i> <tt>lock.owns_lock()</tt> is true and <tt>lock.mutex()</tt> is locked by the calling 
thread. 
<p/>
-12- <i>Throws:</i> <ins>Nothing</ins><del><tt>system_error</tt> when an exception is required (30.2.2)</del>.
<p/>
<del>-13- <i>Error conditions:</i></del>
</p>
<ul>
<li><p><del>equivalent error condition from <tt>lock.lock()</tt> or <tt>lock.unlock()</tt>.</del></p></li>
</ul>
</blockquote>

<blockquote>
<pre>
template &lt;class Predicate&gt;
void wait(unique_lock&lt;mutex&gt;&amp; lock, Predicate pred);
</pre><blockquote>
<p>
[&hellip;]
<p/>
<ins>-?- <i>Remarks:</i> If the function fails to meet the postcondition, <tt>std::terminate()</tt> shall be called 
(14.5.1 <a href="https://timsong-cpp.github.io/cppwp/except.terminate">[except.terminate]</a>). [<i>Note:</i> This can happen if the re-locking of the mutex throws an 
exception. &mdash; <i>end note</i>]</ins>
<p/>
-16- <i>Postcondition:</i> <tt>lock.owns_lock()</tt> is true and <tt>lock.mutex()</tt> is locked by the calling 
thread.
<p/>
-17- <i>Throws:</i> <del><tt>system_error</tt> when an exception is required (30.2.2),</del> timeout-related exceptions 
(30.2.4)<del>,</del> or any exception thrown by <tt>pred</tt>.
<p/>
<del>-18- <i>Error conditions:</i></del>
</p>
<ul>
<li><p><del>equivalent error condition from <tt>lock.lock()</tt> or <tt>lock.unlock()</tt>.</del></p></li>
</ul>
</blockquote></blockquote>

<blockquote>
<pre>
template &lt;class Clock, class Duration&gt;
  cv_status wait_until(unique_lock&lt;mutex&gt;&amp; lock,
    const chrono::time_point&lt;Clock, Duration&gt;&amp; abs_time);
</pre><blockquote>
<p>
[&hellip;]
<p/>
-20- <i>Effects:</i> 
</p>
<ul>
<li><p>[&hellip;]</p></li>
<li><p>If the function exits via an exception, <tt>lock.lock()</tt> shall be called prior to exiting the function
<del>scope</del>.</p></li>
</ul>
<p>
<ins>-?- <i>Remarks:</i> If the function fails to meet the postcondition, <tt>std::terminate()</tt> shall be called 
(14.5.1 <a href="https://timsong-cpp.github.io/cppwp/except.terminate">[except.terminate]</a>). [<i>Note:</i> This can happen if the re-locking of the mutex throws an 
exception. &mdash; <i>end note</i>]</ins>
<p/>
-21- <i>Postcondition:</i> <tt>lock.owns_lock()</tt> is true and <tt>lock.mutex()</tt> is locked by the calling 
thread.
<p/>
[&hellip;]
<p/>
-23- <i>Throws:</i> <del><tt>system_error</tt> when an exception is required (30.2.2) or</del> timeout-related 
exceptions (30.2.4).
<p/>
<del>-24- <i>Error conditions:</i></del>
</p>
<ul>
<li><p><del>equivalent error condition from <tt>lock.lock()</tt> or <tt>lock.unlock()</tt>.</del></p></li>
</ul>
</blockquote></blockquote>

<blockquote>
<pre>
template &lt;class Rep, class Period&gt;
  cv_status wait_for(unique_lock&lt;mutex&gt;&amp; lock,
    const chrono::duration&lt;Rep, Period&gt;&amp; rel_time);
</pre><blockquote>
<p>
[&hellip;]
<p/>
<ins>-?- <i>Remarks:</i> If the function fails to meet the postcondition, <tt>std::terminate()</tt> shall be called 
(14.5.1 <a href="https://timsong-cpp.github.io/cppwp/except.terminate">[except.terminate]</a>). [<i>Note:</i> This can happen if the re-locking of the mutex throws an 
exception. &mdash; <i>end note</i>]</ins>
<p/>
-28- <i>Postcondition:</i> <tt>lock.owns_lock()</tt> is true and <tt>lock.mutex()</tt> is locked by the calling 
thread.
<p/>
[&hellip;]
<p/>
-29- <i>Throws:</i> <del><tt>system_error</tt> when an exception is required (30.2.2) or</del> timeout-related 
exceptions (30.2.4).
<p/>
<del>-30- <i>Error conditions:</i></del>
</p>
<ul>
<li><p><del>equivalent error condition from <tt>lock.lock()</tt> or <tt>lock.unlock()</tt>.</del></p></li>
</ul>
</blockquote></blockquote>

<blockquote>
<pre>
template &lt;class Clock, class Duration, class Predicate&gt;
  bool wait_until(unique_lock&lt;mutex&gt;&amp; lock,
    const chrono::time_point&lt;Clock, Duration&gt;&amp; abs_time,
	Predicate pred);
</pre><blockquote>
<p>
[&hellip;]
<p/>
<ins>-?- <i>Remarks:</i> If the function fails to meet the postcondition, <tt>std::terminate()</tt> shall be called 
(14.5.1 <a href="https://timsong-cpp.github.io/cppwp/except.terminate">[except.terminate]</a>). [<i>Note:</i> This can happen if the re-locking of the mutex throws an 
exception. &mdash; <i>end note</i>]</ins>
<p/>
-33- <i>Postcondition:</i> <tt>lock.owns_lock()</tt> is true and <tt>lock.mutex()</tt> is locked by the calling 
thread.
<p/>
[&hellip;]
<p/>
-35- <i>Throws:</i> <del><tt>system_error</tt> when an exception is required (30.2.2),</del> timeout-related exceptions 
(30.2.4)<del>,</del> or any exception thrown by <tt>pred</tt>.
<p/>
<del>-36- <i>Error conditions:</i></del>
</p>
<ul>
<li><p><del>equivalent error condition from <tt>lock.lock()</tt> or <tt>lock.unlock()</tt>.</del></p></li>
</ul>
</blockquote></blockquote>

<blockquote>
<pre>
template &lt;class Rep, class Period, class Predicate&gt;
  bool wait_for(unique_lock&lt;mutex&gt;&amp; lock,
    const chrono::duration&lt;Rep, Period&gt;&amp; rel_time,
	Predicate pred);
</pre><blockquote>
<p>
[&hellip;]
<p/>
<ins>-?- <i>Remarks:</i> If the function fails to meet the postcondition, <tt>std::terminate()</tt> shall be called 
(14.5.1 <a href="https://timsong-cpp.github.io/cppwp/except.terminate">[except.terminate]</a>). [<i>Note:</i> This can happen if the re-locking of the mutex throws an 
exception. &mdash; <i>end note</i>]</ins>
<p/>
-40- <i>Postcondition:</i> <tt>lock.owns_lock()</tt> is true and <tt>lock.mutex()</tt> is locked by the calling 
thread.
<p/>
[&hellip;]
<p/>
-42- <i>Throws:</i> <del><tt>system_error</tt> when an exception is required (30.2.2),</del> timeout-related exceptions 
(30.2.4)<del>,</del> or any exception thrown by <tt>pred</tt>.
<p/>
<del>-43- <i>Error conditions:</i></del>
</p>
<ul>
<li><p><del>equivalent error condition from <tt>lock.lock()</tt> or <tt>lock.unlock()</tt>.</del></p></li>
</ul>
</blockquote></blockquote>

</blockquote>

</li>

<li><p>Edit 32.5.4 <a href="https://timsong-cpp.github.io/cppwp/thread.condition.condvarany">[thread.condition.condvarany]</a> as indicated:</p>

<blockquote><pre>
template&lt;class Lock&gt;
void wait(Lock&amp; lock);
</pre><blockquote>
<p>
[&hellip;]
<p/>
-10- <i>Effects:</i>
</p>
<ul>
<li><p>Atomically calls <tt>lock.unlock()</tt> and blocks on <tt>*this</tt>.</p></li>
<li><p>When unblocked, calls <tt>lock.lock()</tt> (possibly blocking on the lock) and returns.</p></li>
<li><p>The function will unblock when signaled by a call to <tt>notify_one()</tt>, a call to <tt>notify_all()</tt>,
or spuriously.</p></li>
<li><p><del>If the function exits via an exception, <tt>lock.lock()</tt> shall be called prior to exiting the function
scope.</del></p></li>
</ul>
<p>
<ins>-?- <i>Remarks:</i> If the function fails to meet the postcondition, <tt>std::terminate()</tt> shall be called 
(14.5.1 <a href="https://timsong-cpp.github.io/cppwp/except.terminate">[except.terminate]</a>). [<i>Note:</i> This can happen if the re-locking of the mutex throws an 
exception. &mdash; <i>end note</i>]</ins>
<p/>
-11- <i>Postcondition:</i> <tt>lock</tt> is locked by the calling thread. 
<p/>
-12- <i>Throws:</i> <ins>Nothing</ins><del><tt>system_error</tt> when an exception is required (30.2.2)</del>.
<p/>
<del>-13- <i>Error conditions:</i></del>
</p>
<ul>
<li><p><del>equivalent error condition from <tt>lock.lock()</tt> or <tt>lock.unlock()</tt>.</del></p></li>
</ul>

</blockquote>

<blockquote>
<pre>
template &lt;class Lock, class Clock, class Duration&gt;
  cv_status wait_until(Lock&amp; lock, const chrono::time_point&lt;Clock, Duration&gt;&amp; abs_time);
</pre><blockquote>
<p>
[&hellip;]
<p/>
-15- <i>Effects:</i> 
</p>
<ul>
<li><p>[&hellip;]</p></li>
<li><p>If the function exits via an exception, <tt>lock.lock()</tt> shall be called prior to exiting the function
<del>scope</del>.</p></li>
</ul>
<p>
<ins>-?- <i>Remarks:</i> If the function fails to meet the postcondition, <tt>std::terminate()</tt> shall be called 
(14.5.1 <a href="https://timsong-cpp.github.io/cppwp/except.terminate">[except.terminate]</a>). [<i>Note:</i> This can happen if the re-locking of the mutex throws an 
exception. &mdash; <i>end note</i>]</ins>
<p/>
-16- <i>Postcondition:</i> <tt>lock</tt> is locked by the calling thread.
<p/>
[&hellip;]
<p/>
-18- <i>Throws:</i> <del><tt>system_error</tt> when an exception is required (30.2.2) or</del> timeout-related 
exceptions (30.2.4).
<p/>
<del>-19- <i>Error conditions:</i></del>
</p>
<ul>
<li><p><del>equivalent error condition from <tt>lock.lock()</tt> or <tt>lock.unlock()</tt>.</del></p></li>
</ul>
</blockquote></blockquote>

<blockquote>
<pre>
template &lt;class Lock, class Rep, class Period&gt;
  cv_status wait_for(Lock&amp; lock, const chrono::duration&lt;Rep, Period&gt;&amp; rel_time);
</pre><blockquote>
<p>
[&hellip;]
<p/>
<ins>-?- <i>Remarks:</i> If the function fails to meet the postcondition, <tt>std::terminate()</tt> shall be called 
(14.5.1 <a href="https://timsong-cpp.github.io/cppwp/except.terminate">[except.terminate]</a>). [<i>Note:</i> This can happen if the re-locking of the mutex throws an 
exception. &mdash; <i>end note</i>]</ins>
<p/>
-22- <i>Postcondition:</i> <tt>lock</tt> is locked by the calling thread.
<p/>
[&hellip;]
<p/>
-23- <i>Throws:</i> <del><tt>system_error</tt> when an exception is required (30.2.2) or</del> timeout-related 
exceptions (30.2.4).
<p/>
<del>-24- <i>Error conditions:</i></del>
</p>
<ul>
<li><p><del>equivalent error condition from <tt>lock.lock()</tt> or <tt>lock.unlock()</tt>.</del></p></li>
</ul>
</blockquote></blockquote>

</blockquote>

</li>
</ol>






</body>
</html>
